<mujoco model="grq20_v2d4_piperL_front_mount_gripper_hook door scene">
  <include file="grq20_v2d4_piperL_front_mount_gripper_hook.xml"/>

  <statistic center="0.8 0 0.7" extent="2.2"/>

  <visual>
    <headlight diffuse="0.6 0.6 0.6" ambient="0.3 0.3 0.3" specular="0 0 0"/>
    <rgba haze="0.15 0.25 0.35 1"/>
    <global azimuth="-120" elevation="-18"/>
  </visual>

  <asset>
    <texture type="skybox" builtin="gradient" rgb1="0.35 0.48 0.62" rgb2="0.04 0.04 0.05" width="512" height="3072"/>
    <texture type="2d" name="groundplane" builtin="checker" mark="edge" rgb1="0.24 0.28 0.29" rgb2="0.14 0.17 0.18" markrgb="0.8 0.8 0.8" width="300" height="300"/>
    <material name="groundplane" texture="groundplane" texuniform="true" texrepeat="5 5" reflectance="0.18"/>
    <material name="wall_mat" rgba="0.68 0.70 0.69 1"/>
    <material name="door_mat" rgba="0.50 0.42 0.32 1"/>
    <material name="handle_mat" rgba="0.88 0.82 0.68 1"/>
    <material name="frame_mat" rgba="0.22 0.24 0.25 1"/>
  </asset>

  <worldbody>
    <light pos="0 0 2.5" dir="0 0 -1" directional="true"/>
    <geom name="floor" size="0 0 0.05" type="plane" material="groundplane" conaffinity="7" condim="4" friction="1.3 0.08 0.01"/>

    <geom name="left_wall" type="box" pos="1.18 1.23 0.9" size="0.045 0.47 0.90" material="wall_mat" conaffinity="7" condim="3"/>
    <geom name="right_wall" type="box" pos="1.18 -1.23 0.9" size="0.045 0.47 0.90" material="wall_mat" conaffinity="7" condim="3"/>
    <geom name="top_wall" type="box" pos="1.18 0 1.78" size="0.045 0.80 0.10" material="wall_mat" conaffinity="7" condim="3"/>

    <geom name="door_hinge_post" type="cylinder" fromto="1.12 -0.76 0 1.12 -0.76 1.70" size="0.025" material="frame_mat" contype="0" conaffinity="0"/>
    <geom name="door_stop_pull_side" type="box" pos="1.105 0 0.84" size="0.012 0.76 0.81" rgba="0.12 0.12 0.12 0.25" contype="0" conaffinity="0"/>
    <geom name="door_latch_keeper_pull_side" type="box" pos="1.035 0.758 0.895" size="0.010 0.024 0.125" material="frame_mat" conaffinity="7" condim="4" friction="1.0 0.05 0.005" margin="0.001"/>
    <geom name="door_latch_keeper_push_side" type="box" pos="1.095 0.758 0.895" size="0.010 0.024 0.125" material="frame_mat" conaffinity="7" condim="4" friction="1.0 0.05 0.005" margin="0.001"/>

    <body name="door_panel" pos="1.12 -0.74 0">
      <joint name="door_hinge" type="hinge" axis="0 0 1" limited="true" range="-1.75 1.75" damping="0.60" frictionloss="0.05" armature="0.04"/>
      <inertial pos="0 0.72 0.84" mass="60.0" diaginertia="23.49 13.13 10.38"/>
      <geom name="door_leaf" type="box" pos="0 0.72 0.84" size="0.025 0.72 0.81" material="door_mat" conaffinity="7" condim="3" friction="0.85 0.05 0.01"/>
      <geom name="door_push_plate" type="box" pos="-0.028 1.08 0.88" size="0.006 0.12 0.20" rgba="0.18 0.19 0.20 1" conaffinity="7" condim="3"/>
      <site name="door_handle_site" pos="-0.205 1.21 0.90" size="0.015" rgba="0 1 1 1"/>

      <body name="l_handle" pos="-0.055 1.08 0.90">
        <joint name="door_handle_pitch" type="hinge" axis="1 0 0" limited="true" range="-0.60 0.20" damping="0.20" frictionloss="0.03" stiffness="0.4" springref="0"/>
        <inertial pos="-0.11 0.08 0" mass="0.25" diaginertia="0.002 0.002 0.001"/>
        <geom name="handle_spindle" type="capsule" fromto="0 0 0 -0.15 0 0" size="0.0075" material="handle_mat" conaffinity="7" condim="4" friction="0.05 0.005 0.0005" margin="0.0005"/>
        <geom name="handle_elbow" type="sphere" pos="-0.15 0 0" size="0.0100" material="handle_mat" conaffinity="7" condim="4" friction="0.05 0.005 0.0005" margin="0.0005"/>
        <geom name="handle_lever_flat" type="box" pos="-0.15 0.1325 0" size="0.0060 0.1325 0.0045" material="handle_mat" conaffinity="7" condim="4" friction="0.05 0.005 0.0005" margin="0.0005"/>
        <geom name="handle_lever_top_round" type="capsule" fromto="-0.15 0.012 0.0060 -0.15 0.253 0.0060" size="0.0035" material="handle_mat" conaffinity="7" condim="4" friction="0.05 0.005 0.0005" margin="0.0005"/>
        <geom name="handle_lever_bottom_round" type="capsule" fromto="-0.15 0.012 -0.0060 -0.15 0.253 -0.0060" size="0.0035" material="handle_mat" conaffinity="7" condim="4" friction="0.05 0.005 0.0005" margin="0.0005"/>
        <geom name="handle_lever_outer_round" type="capsule" fromto="-0.1560 0.012 0 -0.1560 0.253 0" size="0.0035" material="handle_mat" conaffinity="7" condim="4" friction="0.05 0.005 0.0005" margin="0.0005"/>
        <geom name="handle_tip" type="sphere" pos="-0.15 0.265 0" size="0.0100" material="handle_mat" conaffinity="7" condim="4" friction="0.05 0.005 0.0005" margin="0.0005"/>
        <geom name="handle_tip_lip" type="capsule" fromto="-0.15 0.265 -0.012 -0.15 0.265 0.012" size="0.0045" material="handle_mat" conaffinity="7" condim="4" friction="0.05 0.005 0.0005" margin="0.0005"/>
        <geom name="door_latch_bolt" type="box" pos="0 0.390 0" size="0.012 0.055 0.012" material="handle_mat" conaffinity="7" condim="4" friction="1.0 0.05 0.005" margin="0.001"/>
      </body>
    </body>
  </worldbody>
</mujoco>
